Workbook

Sheet README
B2: ANCHOR ENGAGE
B3: May 2026 - Spring in Bloom
B4: Connecting residents to what matters
B5: An Anchor Care Consulting product
B7: May celebrates spring at its peak: gardens bloom, family gathers for Mother's Day, and the country pauses on Memorial Day to remember those who served. This month's program leans into flowers, picnics, derby fun, patriotic music, berry season, warm-weather socials - and we travel to Italy on May 21.
B9: WORKBOOK CONTENTS
B10: Calendar - MC / AL / IL: Monthly grid for each care level. Print landscape.
B11: Daily - MC / AL / IL: Detailed activity tables for each level: 31 days x 7 slots, with the 6-card afternoon menu inline.
B12: Bonus Events: Six big planned events for the month, shared across levels.
B13: Holidays: Quick reference for theme tie-ins.
B14: Roster: Add residents with care-level tags. Names auto-flow into Charting tabs.
B15: Charting - MC / AL / IL: Per-resident, per-day, per-slot attendance. Auto-totals. A/O/D/N/A codes.
... B33: Once-a-month travel day where every activity is themed to one country. Today: Italy. Italian opera, photos of Tuscany and the Amalfi Coast, pasta lunch, Italian language phrases on every table, gelato or cannoli for dessert, and an Italian movie classic in the evening.

Sheet Calendar - MC
A1: MAY 2026 - MEMORY CARE
A2: Spring in Bloom - Anchor Engage by Anchor Care Consulting
A3: MONDAY | B3: TUESDAY | C3: WEDNESDAY | D3: THURSDAY | E3: FRIDAY | F3: SATURDAY | G3: SUNDAY
E4: 1 May Day & National Mother Goose Day | F4: 2 Kentucky Derby Day (1st Saturday) | G4: 3 National Garden Meditation Day
E5: 9:00 AM: Sensory Spring Stretch 10:30 AM: 'Welcome to May' Trivia 12:00 PM: 'Welcome to May' Word Search 1:30 PM: Hand Massage with Lotion 2:00 PM: 6-choice menu (PM) 4:00 PM: Word Search: May Day & Spring 6:30 PM: Lawrence Welk + Chamomile Tea | F5: 9:00 AM: Music & Movement: Marching Songs 10:30 AM: Kentucky Derby Trivia 12:00 PM: Sports Headlines + Famous Horses Trivia 1:30 PM: Derby Day Reading 2:00 PM: 6-choice menu (PM) 4:00 PM: Word Search: Kentucky Derby 6:30 PM: Derby Music & Mint Lemonade | G5: 9:00 AM: Sunday Calm Stretch + Hymn Hour 10:30 AM: Garden & Plants Trivia 12:00 PM: Sunday Comics Read-Aloud + Garden Word List 1:30 PM: Sunday Hymn Listening 2:00 PM: 6-choice menu (PM) 4:00 PM: Word Search: Garden Meditation 6:30 PM: Hymn Sing & Comfort Time
A6: 4 Star Wars Day - 'May the 4th Be With You' | B6: 5 Cinco de Mayo | C6: 6 National Nurses Day & National Beverage Day | D6: 7 National Roast Leg of Lamb Day | E6: 8 V-E Day (Victory in Europe, 1945) & No Socks Day | F6: 9 National Lost Sock Memorial Day & National Train Day | G6: 10 Mother's Day & National Shrimp Day
A7: 9:00 AM: Bean Bag Toss Warm-up 10:30 AM: Star Wars Trivia 12:00 PM: Front-Page News + Movie Trivia 1:30 PM: Photo Album Browsing 2:00 PM: 6-choice menu (PM) 4:00 PM: Word Search: Star Wars Day 6:30 PM: Old TV Show Lounge (I Love Lucy / Andy Griffith) | B7: 9:00 AM: Maracas & Music Movement 10:30 AM: Mexico & Cinco de Mayo Trivia 12:00 PM: Cinco de Mayo Word Search (Spanish-English) 1:30 PM: Pet Therapy Visit 2:00 PM: 6-choice menu (PM) 4:00 PM: Word Search: Cinco de Mayo 6:30 PM: Lawrence Welk + Chamomile Tea | C7: 9:00 AM: Slow Stretch + Hand Massage 10:30 AM: Famous Nurses Trivia 12:00 PM: Newspaper + 'Things My Mom/Nurse Said' Reminiscence 1:30 PM: Aromatherapy with Lavender 2:00 PM: 6-choice menu (PM) 4:00 PM: Word Search: Nurses Day 6:30 PM: Soft Music + Hand Lotion Round | D7: 9:00 AM: Walking Circle (Hallway Loop) 10:30 AM: Greek & Mediterranean Trivia 12:00 PM: Garden Section + Flower Crossword (Easy) 1:30 PM: Greek Mythology Story Hour 2:00 PM: 6-choice menu (PM) 4:00 PM: Word Search: Garden Crossword Words 6:30 PM: Hymn Sing & Comfort Time | E7: 9:00 AM: Big Band Seated Dance 10:30 AM: WWII & V-E Day Trivia 12:00 PM: V-E Day History Read + 1940s Word Search 1:30 PM: V-E Day Memory Hour 2:00 PM: 6-choice menu (PM) 4:00 PM: Word Search: V-E Day 1945 6:30 PM: Old TV Show Lounge (I Love Lucy / Andy Griffith) | F7: 9:00 AM: Train Whistle Warm-up 10:30 AM: Trains & Travel Trivia 12:00 PM: Travel Section + Train Trivia 1:30 PM: Music Listening Hour 2:00 PM: 6-choice menu (PM) 4:00 PM: Word Search: National Train Day 6:30 PM: Lawrence Welk + Chamomile Tea | G7: 9:00 AM: Mother's Day Gentle Stretch 10:30 AM: Famous Mothers Trivia 12:00 PM: Sunday Paper + 'Mom's Wisdom' Word List 1:30 PM: Mother's Day Memory Hour 2:00 PM: 6-choice menu (PM) 4:00 PM: Word Search: Mother's Day 6:30 PM: Mother's Day Quiet Music Hour
A8: 11 National Eat What You Want Day | B8: 12 International Nurses Day & National Limerick Day | C8: 13 National Apple Pie Day & National Frog Jumping Day | D8: 14 National Buttermilk Biscuit Day | E8: 15 National Chocolate Chip Day | F8: 16 Armed Forces Day (3rd Saturday) & National BBQ Day | G8: 17 National Walnut Day
A9: 9:00 AM: Balance Practice with Aide Support 10:30 AM: Food Favorites Trivia 12:00 PM: Food Section + 'Eat What You Want' Vote 1:30 PM: Pet Therapy Visit 2:00 PM: 6-choice menu (PM) 4:00 PM: Word Search: Eat What You Want 6:30 PM: Hymn Sing & Comfort Time | B9: 9:00 AM: Tai Chi (Seated, Very Slow) 10:30 AM: Limericks & Wordplay Trivia 12:00 PM: Limerick Day Special 1:30 PM: Hand Massage + Soft Music 2:00 PM: 6-choice menu (PM) 4:00 PM: Limerick Composing Workshop 6:30 PM: Old TV Show Lounge (I Love Lucy / Andy Griffith) | C9: 9:00 AM: Apple Pie Energizer 10:30 AM: Apple Pie Trivia 12:00 PM: Food Section + Apple Pie Recipe Read-Aloud 1:30 PM: Hand Massage with Lotion 2:00 PM: 6-choice menu (PM) 4:00 PM: Word Search: Apple Pie & Frogs 6:30 PM: Lawrence Welk + Chamomile Tea | D9: 9:00 AM: Country Music Movement: 'Biscuit Stretch' 10:30 AM: Southern Cooking Trivia 12:00 PM: Food Section + Biscuit Recipe Reminiscence 1:30 PM: Sensory Bin Time 2:00 PM: 6-choice menu (PM) 4:00 PM: Word Search: Buttermilk Biscuit 6:30 PM: Biscuit + Tea Wind-Down | E9: 9:00 AM: Chair Yoga: Shoulders & Neck 10:30 AM: Cookies & Sweets Trivia 12:00 PM: Newspaper + Chocolate Chip Cookie History 1:30 PM: Music Listening Hour 2:00 PM: 6-choice menu (PM) 4:00 PM: Word Search: Chocolate Chip 6:30 PM: Hymn Sing & Comfort Time | F9: 9:00 AM: Patriotic Marching Music 10:30 AM: Armed Forces Trivia 12:00 PM: Newspaper + Military Branches Word Match 1:30 PM: Veterans Photo Reminiscence 2:00 PM: 6-choice menu (PM) 4:00 PM: Word Search: Armed Forces Day 6:30 PM: USO Musical Hour | G9: 9:00 AM: Sunday Calm Stretch + Hymns 10:30 AM: Walnut & Trees Trivia 12:00 PM: Sunday Comics + Walnut Trivia 1:30 PM: Walnut Bread + Quiet Hour 2:00 PM: 6-choice menu (PM) 4:00 PM: Word Search: Walnut Day 6:30 PM: Lawrence Welk + Chamomile Tea
A10: 18 International Museum Day | B10: 19 National Devil's Food Cake Day | C10: 20 National Pick Strawberries Day | D10: 21 🇮🇹 TRAVEL DAY: Italy | E10: 22 National Maritime Day & National Vanilla Pudding Day | F10: 23 National Lucky Penny Day & World Turtle Day | G10: 24 National Scavenger Hunt Day
A11: 9:00 AM: Hallway Walk + Art Stops 10:30 AM: Famous Museums Trivia 12:00 PM: Newspaper + Art Trivia 1:30 PM: Aromatherapy with Lavender 2:00 PM: 6-choice menu (PM) 4:00 PM: Word Search: Museum Day 6:30 PM: Soft Music + Hand Lotion Round | B11: 9:00 AM: Resistance Band: Light Arms Only 10:30 AM: Cake & Chocolate Trivia 12:00 PM: Food Section + Devil's Food Cake History 1:30 PM: Hand Massage with Lotion 2:00 PM: 6-choice menu (PM) 4:00 PM: Word Search: Devil's Food Cake 6:30 PM: Hymn Sing & Comfort Time | C11: 9:00 AM: Strawberry Picking Pretend 10:30 AM: Strawberry & Berry Trivia 12:00 PM: Newspaper + Strawberry Recipe Read 1:30 PM: Sensory Bin Time 2:00 PM: 6-choice menu (PM) 4:00 PM: Word Search: Strawberry Picking 6:30 PM: Strawberry Sundae Wind-Down | D11: 9:00 AM: Italian Stretch & Opera 10:30 AM: ITALY TRAVEL DAY Trivia 12:00 PM: Headlines + Italian Travel Section 1:30 PM: 🇮🇹 Italian Music & Espresso 2:00 PM: 6-choice menu (PM) 4:00 PM: 🇮🇹 Italian Word Find 6:30 PM: 🇮🇹 Italian Cinema Night: 'Life Is Beautiful' (1997) | E11: 9:00 AM: Maritime Sing-Along Movement 10:30 AM: Maritime & Sailing Trivia 12:00 PM: Newspaper + Maritime Day Word Search 1:30 PM: Photo Album Browsing 2:00 PM: 6-choice menu (PM) 4:00 PM: Word Search: Maritime Day 6:30 PM: Soft Music + Hand Lotion Round | F11: 9:00 AM: Walking Loop + Lucky Penny Hunt 10:30 AM: Lucky Penny & Turtles Trivia 12:00 PM: Newspaper + Penny Trivia 1:30 PM: Pet Therapy Visit 2:00 PM: 6-choice menu (PM) 4:00 PM: Word Search: Lucky Penny / Turtle 6:30 PM: Hymn Sing & Comfort Time | G11: 9:00 AM: Sunday Calm Stretch + Quiet Time 10:30 AM: Scavenger & Discovery Trivia 12:00 PM: Sunday Paper + Scavenger Hunt Word List 1:30 PM: Sunday Reflection Hour 2:00 PM: 6-choice menu (PM) 4:00 PM: Word Search: Scavenger Hunt 6:30 PM: Old TV Show Lounge (I Love Lucy / Andy Griffith)
A12: 25 MEMORIAL DAY & National Wine Day | B12: 26 National Blueberry Cheesecake Day & National Paper Airplane Day | C12: 27 National Grape Popsicle Day & Sun Screen Day | D12: 28 National Hamburger Day & Senior Health & Fitness Day | E12: 29 JFK's Birthday & National Coq au Vin Day | F12: 30 National Mint Julep Day | G12: 31 National Macaroon Day
A13: 9:00 AM: Patriotic Movement + Hand on Heart 10:30 AM: Memorial Day Trivia 12:00 PM: Newspaper + Memorial Day Reading 1:30 PM: Veterans Reflection Hour 2:00 PM: 6-choice menu (PM) 4:00 PM: Memorial Day Word Find 6:30 PM: Memorial Day Music Reflection | B13: 9:00 AM: Easy Full Body Stretch 10:30 AM: Blueberry & Paper Airplane Trivia 12:00 PM: Newspaper + Paper Airplane Folding 1:30 PM: Sensory Bin Time 2:00 PM: 6-choice menu (PM) 4:00 PM: Word Search: Paper Airplane / Cake 6:30 PM: Soft Music + Hand Lotion Round | C13: 9:00 AM: Gentle Sun Salutation (Seated) 10:30 AM: Sun & Summer Trivia 12:00 PM: Newspaper + Sun & Skin Care Tips 1:30 PM: Music Listening Hour 2:00 PM: 6-choice menu (PM) 4:00 PM: Word Search: Sun & Sun Screen 6:30 PM: Hymn Sing & Comfort Time | D13: 9:00 AM: Health Fair Warm-Up 10:30 AM: Hamburger & Burger Trivia 12:00 PM: Newspaper + Health Tips Trivia 1:30 PM: Photo Album Browsing 2:00 PM: 6-choice menu (PM) 4:00 PM: Word Search: Hamburger Day 6:30 PM: Old TV Show Lounge (I Love Lucy / Andy Griffith) | E13: 9:00 AM: Camelot Era Seated Dance 10:30 AM: 1960s & JFK Trivia 12:00 PM: Newspaper + JFK Reminiscence Word List 1:30 PM: Pet Therapy Visit 2:00 PM: 6-choice menu (PM) 4:00 PM: Word Search: 60s Decade 6:30 PM: Lawrence Welk + Chamomile Tea | F13: 9:00 AM: Country Movement Saturday 10:30 AM: Mint Julep & Drinks Trivia 12:00 PM: Newspaper + Mint Julep Recipe Read 1:30 PM: Aromatherapy with Lavender 2:00 PM: 6-choice menu (PM) 4:00 PM: Word Search: Mint Julep / Derby Closing 6:30 PM: Soft Music + Hand Lotion Round | G13: 9:00 AM: Closing Stretch + Thank You Circle 10:30 AM: May in Review Trivia 12:00 PM: Sunday Comics + 'Goodbye May' Word List 1:30 PM: May in Review Slideshow 2:00 PM: 6-choice menu (PM) 4:00 PM: Word Search: Macaroon & May Closing 6:30 PM: May Closing Music Hour
A15: GOLD = Major Holiday | LIGHT GOLD = Bonus Event Day | ORANGE = TRAVEL DAY (May 21 - Italy) | LIGHT BLUE = Weekend | Times shown are defaults - can be adjusted.

Sheet Calendar - AL
A1: MAY 2026 - ASSISTED LIVING
A2: Spring in Bloom - Anchor Engage by Anchor Care Consulting
A3: MONDAY | B3: TUESDAY | C3: WEDNESDAY | D3: THURSDAY | E3: FRIDAY | F3: SATURDAY | G3: SUNDAY
E4: 1 May Day & National Mother Goose Day | F4: 2 Kentucky Derby Day (1st Saturday) | G4: 3 National Garden Meditation Day
E5: 9:00 AM: Chair Yoga: Spring Awakening 10:30 AM: 'Welcome to May' Trivia 12:00 PM: 'Welcome to May' Word Search 1:30 PM: Quiet Reading Hour 2:00 PM: 6-choice menu (PM) 4:00 PM: Word Search: May Day & Spring 6:30 PM: 'Driving Miss Daisy' (1989) - Wind Down | F5: 9:00 AM: Derby Day Warm-Up 10:30 AM: Kentucky Derby Trivia 12:00 PM: Sports Headlines + Famous Horses Trivia 1:30 PM: Derby Day Reading 2:00 PM: 6-choice menu (PM) 4:00 PM: Word Search: Kentucky Derby 6:30 PM: Kentucky Derby Watch Party (live TV) - Wind Down | G5: 9:00 AM: Sunday Stretch & Hymn Hour 10:30 AM: Garden & Plants Trivia 12:00 PM: Sunday Comics Read-Aloud + Garden Word List 1:30 PM: Sunday Hymn Listening 2:00 PM: 6-choice menu (PM) 4:00 PM: Word Search: Garden Meditation 6:30 PM: Sing-Along Hour
A6: 4 Star Wars Day - 'May the 4th Be With You' | B6: 5 Cinco de Mayo | C6: 6 National Nurses Day & National Beverage Day | D6: 7 National Roast Leg of Lamb Day | E6: 8 V-E Day (Victory in Europe, 1945) & No Socks Day | F6: 9 National Lost Sock Memorial Day & National Train Day | G6: 10 Mother's Day & National Shrimp Day
A7: 9:00 AM: Star Wars 'Jedi Training' Stretch 10:30 AM: Star Wars Trivia 12:00 PM: Front-Page News + Movie Trivia 1:30 PM: Coloring & Tea 2:00 PM: 6-choice menu (PM) 4:00 PM: Word Search: Star Wars Day 6:30 PM: Movie + Popcorn | B7: 9:00 AM: Salsa Dance Movement (Seated) 10:30 AM: Mexico & Cinco de Mayo Trivia 12:00 PM: Cinco de Mayo Word Search (Spanish-English) 1:30 PM: Birdwatching Hour 2:00 PM: 6-choice menu (PM) 4:00 PM: Word Search: Cinco de Mayo 6:30 PM: Music & Conversation Lounge | C7: 9:00 AM: Resistance Band Workout: Strong Like a Nurse 10:30 AM: Famous Nurses Trivia 12:00 PM: Newspaper + 'Things My Mom/Nurse Said' Reminiscence 1:30 PM: Letter Writing Hour 2:00 PM: 6-choice menu (PM) 4:00 PM: Word Search: Nurses Day 6:30 PM: Game Lounge: Cards & Conversation | D7: 9:00 AM: Walking Club: Indoor Lap or Garden Stroll 10:30 AM: Greek & Mediterranean Trivia 12:00 PM: Garden Section + Flower Crossword (Easy) 1:30 PM: Greek Mythology Story Hour 2:00 PM: 6-choice menu (PM) 4:00 PM: Word Search: Garden Crossword Words 6:30 PM: 'On Golden Pond' (1981) - Wind Down | E7: 9:00 AM: Dance Movement: Big Band Era 10:30 AM: WWII & V-E Day Trivia 12:00 PM: V-E Day History Read + 1940s Word Search 1:30 PM: V-E Day Memory Hour 2:00 PM: 6-choice menu (PM) 4:00 PM: Word Search: V-E Day 1945 6:30 PM: Mother's Day Tea wind-down with soft music - Wind Down | F7: 9:00 AM: Marching Band Movement 10:30 AM: Trains & Travel Trivia 12:00 PM: Travel Section + Train Trivia 1:30 PM: Card Lounge: Solo or Pairs 2:00 PM: 6-choice menu (PM) 4:00 PM: Word Search: National Train Day 6:30 PM: Music & Conversation Lounge | G7: 9:00 AM: Sunday Gentle Stretch + Mom's Favorite Songs 10:30 AM: Famous Mothers Trivia 12:00 PM: Sunday Paper + 'Mom's Wisdom' Word List 1:30 PM: Mother's Day Memory Hour 2:00 PM: 6-choice menu (PM) 4:00 PM: Word Search: Mother's Day 6:30 PM: 'Steel Magnolias' (1989) - Wind Down
A8: 11 National Eat What You Want Day | B8: 12 International Nurses Day & National Limerick Day | C8: 13 National Apple Pie Day & National Frog Jumping Day | D8: 14 National Buttermilk Biscuit Day | E8: 15 National Chocolate Chip Day | F8: 16 Armed Forces Day (3rd Saturday) & National BBQ Day | G8: 17 National Walnut Day
A9: 9:00 AM: Standing/Seated Balance Practice 10:30 AM: Food Favorites Trivia 12:00 PM: Food Section + 'Eat What You Want' Vote 1:30 PM: Birdwatching Hour 2:00 PM: 6-choice menu (PM) 4:00 PM: Word Search: Eat What You Want 6:30 PM: Sing-Along Hour | B9: 9:00 AM: Tai Chi Basics (Seated) 10:30 AM: Limericks & Wordplay Trivia 12:00 PM: Limerick Day Special 1:30 PM: Hand Massage + Soft Music 2:00 PM: 6-choice menu (PM) 4:00 PM: Limerick Composing Workshop 6:30 PM: Movie + Popcorn | C9: 9:00 AM: Apple Pie Energizer 10:30 AM: Apple Pie Trivia 12:00 PM: Food Section + Apple Pie Recipe Read-Aloud 1:30 PM: Quiet Reading Hour 2:00 PM: 6-choice menu (PM) 4:00 PM: Word Search: Apple Pie & Frogs 6:30 PM: Music & Conversation Lounge | D9: 9:00 AM: Country Music Movement: 'Biscuit Stretch' 10:30 AM: Southern Cooking Trivia 12:00 PM: Food Section + Biscuit Recipe Reminiscence 1:30 PM: Magazine Page-Through 2:00 PM: 6-choice menu (PM) 4:00 PM: Word Search: Buttermilk Biscuit 6:30 PM: Biscuit + Tea Wind-Down | E9: 9:00 AM: Chair Yoga: Shoulder & Neck Relief 10:30 AM: Cookies & Sweets Trivia 12:00 PM: Newspaper + Chocolate Chip Cookie History 1:30 PM: Card Lounge: Solo or Pairs 2:00 PM: 6-choice menu (PM) 4:00 PM: Word Search: Chocolate Chip 6:30 PM: Sing-Along Hour | F9: 9:00 AM: Patriotic Marching Movement 10:30 AM: Armed Forces Trivia 12:00 PM: Newspaper + Military Branches Word Match 1:30 PM: Veterans Photo Reminiscence 2:00 PM: 6-choice menu (PM) 4:00 PM: Word Search: Armed Forces Day 6:30 PM: 'The Best Years of Our Lives' (1946) Pt 1 - Wind Down | G9: 9:00 AM: Sunday Stretch with Soft Hymns 10:30 AM: Walnut & Trees Trivia 12:00 PM: Sunday Comics + Walnut Trivia 1:30 PM: Walnut Bread + Quiet Hour 2:00 PM: 6-choice menu (PM) 4:00 PM: Word Search: Walnut Day 6:30 PM: Music & Conversation Lounge
A10: 18 International Museum Day | B10: 19 National Devil's Food Cake Day | C10: 20 National Pick Strawberries Day | D10: 21 🇮🇹 TRAVEL DAY: Italy | E10: 22 National Maritime Day & National Vanilla Pudding Day | F10: 23 National Lucky Penny Day & World Turtle Day | G10: 24 National Scavenger Hunt Day
A11: 9:00 AM: Walking Club: Museum Walk 10:30 AM: Famous Museums Trivia 12:00 PM: Newspaper + Art Trivia 1:30 PM: Letter Writing Hour 2:00 PM: 6-choice menu (PM) 4:00 PM: Word Search: Museum Day 6:30 PM: Game Lounge: Cards & Conversation | B11: 9:00 AM: Resistance Band: Lower Body Focus 10:30 AM: Cake & Chocolate Trivia 12:00 PM: Food Section + Devil's Food Cake History 1:30 PM: Quiet Reading Hour 2:00 PM: 6-choice menu (PM) 4:00 PM: Word Search: Devil's Food Cake 6:30 PM: Sing-Along Hour | C11: 9:00 AM: Strawberry Picking Movement 10:30 AM: Strawberry & Berry Trivia 12:00 PM: Newspaper + Strawberry Recipe Read 1:30 PM: Magazine Page-Through 2:00 PM: 6-choice menu (PM) 4:00 PM: Word Search: Strawberry Picking 6:30 PM: Strawberry Sundae Wind-Down | D11: 9:00 AM: Italian Stretch & Opera 10:30 AM: ITALY TRAVEL DAY Trivia 12:00 PM: Headlines + Italian Travel Section 1:30 PM: 🇮🇹 Italian Music & Espresso 2:00 PM: 6-choice menu (PM) 4:00 PM: 🇮🇹 Italian Word Find 6:30 PM: 🇮🇹 Italian Cinema Night: 'Life Is Beautiful' (1997) | E11: 9:00 AM: Dance Movement: Big Band & Maritime Songs 10:30 AM: Maritime & Sailing Trivia 12:00 PM: Newspaper + Maritime Day Word Search 1:30 PM: Coloring & Tea 2:00 PM: 6-choice menu (PM) 4:00 PM: Word Search: Maritime Day 6:30 PM: Game Lounge: Cards & Conversation | F11: 9:00 AM: Walking Club: Garden + Penny Pickup 10:30 AM: Lucky Penny & Turtles Trivia 12:00 PM: Newspaper + Penny Trivia 1:30 PM: Birdwatching Hour 2:00 PM: 6-choice menu (PM) 4:00 PM: Word Search: Lucky Penny / Turtle 6:30 PM: Sing-Along Hour | G11: 9:00 AM: Sunday Stretch + Quiet Reflection 10:30 AM: Scavenger & Discovery Trivia 12:00 PM: Sunday Paper + Scavenger Hunt Word List 1:30 PM: Sunday Reflection Hour 2:00 PM: 6-choice menu (PM) 4:00 PM: Word Search: Scavenger Hunt 6:30 PM: Movie + Popcorn
A12: 25 MEMORIAL DAY & National Wine Day | B12: 26 National Blueberry Cheesecake Day & National Paper Airplane Day | C12: 27 National Grape Popsicle Day & Sun Screen Day | D12: 28 National Hamburger Day & Senior Health & Fitness Day | E12: 29 JFK's Birthday & National Coq au Vin Day | F12: 30 National Mint Julep Day | G12: 31 National Macaroon Day
A13: 9:00 AM: Patriotic Movement Hour 10:30 AM: Memorial Day Trivia 12:00 PM: Newspaper + Memorial Day Reading 1:30 PM: Veterans Reflection Hour 2:00 PM: 6-choice menu (PM) 4:00 PM: Memorial Day Word Find 6:30 PM: 'The Notebook' (2004) - Memorial Day evening - Wind Down | B13: 9:00 AM: Resistance Band: Full Body Quick Routine 10:30 AM: Blueberry & Paper Airplane Trivia 12:00 PM: Newspaper + Paper Airplane Folding 1:30 PM: Magazine Page-Through 2:00 PM: 6-choice menu (PM) 4:00 PM: Word Search: Paper Airplane / Cake 6:30 PM: Game Lounge: Cards & Conversation | C13: 9:00 AM: Chair Yoga: Sun Salutation Adaptation 10:30 AM: Sun & Summer Trivia 12:00 PM: Newspaper + Sun & Skin Care Tips 1:30 PM: Card Lounge: Solo or Pairs 2:00 PM: 6-choice menu (PM) 4:00 PM: Word Search: Sun & Sun Screen 6:30 PM: Sing-Along Hour | D13: 9:00 AM: Senior Health & Fitness Fair Warm-Up 10:30 AM: Hamburger & Burger Trivia 12:00 PM: Newspaper + Health Tips Trivia 1:30 PM: Coloring & Tea 2:00 PM: 6-choice menu (PM) 4:00 PM: Word Search: Hamburger Day 6:30 PM: Movie + Popcorn | E13: 9:00 AM: Dance Movement: Camelot Era 10:30 AM: 1960s & JFK Trivia 12:00 PM: Newspaper + JFK Reminiscence Word List 1:30 PM: Birdwatching Hour 2:00 PM: 6-choice menu (PM) 4:00 PM: Word Search: 60s Decade 6:30 PM: 'Hidden Figures' (2016) - Wind Down | F13: 9:00 AM: Saturday Morning Country Movement 10:30 AM: Mint Julep & Drinks Trivia 12:00 PM: Newspaper + Mint Julep Recipe Read 1:30 PM: Letter Writing Hour 2:00 PM: 6-choice menu (PM) 4:00 PM: Word Search: Mint Julep / Derby Closing 6:30 PM: Game Lounge: Cards & Conversation | G13: 9:00 AM: Sunday Closing Stretch 10:30 AM: May in Review Trivia 12:00 PM: Sunday Comics + 'Goodbye May' Word List 1:30 PM: May in Review Slideshow 2:00 PM: 6-choice menu (PM) 4:00 PM: Word Search: Macaroon & May Closing 6:30 PM: Sing-Along Hour
A15: GOLD = Major Holiday | LIGHT GOLD = Bonus Event Day | ORANGE = TRAVEL DAY (May 21 - Italy) | LIGHT BLUE = Weekend | Times shown are defaults - can be adjusted.

Sheet Calendar - IL
A1: MAY 2026 - INDEPENDENT
A2: Spring in Bloom - Anchor Engage by Anchor Care Consulting
A3: MONDAY | B3: TUESDAY | C3: WEDNESDAY | D3: THURSDAY | E3: FRIDAY | F3: SATURDAY | G3: SUNDAY
E4: 1 May Day & National Mother Goose Day | F4: 2 Kentucky Derby Day (1st Saturday) | G4: 3 National Garden Meditation Day
E5: 9:00 AM: Walking Club + Yoga (Choice) 10:30 AM: 'Welcome to May' Trivia 12:00 PM: 'Welcome to May' Word Search 1:30 PM: Book Club Quiet Reading 2:00 PM: 6-choice menu (PM) 4:00 PM: Word Search: May Day & Spring 6:30 PM: Movie Night: 'Driving Miss Daisy' (1989) | F5: 9:00 AM: Resistance Band Strength Class 10:30 AM: Kentucky Derby Trivia 12:00 PM: Sports Headlines + Famous Horses Trivia 1:30 PM: Derby Day Reading 2:00 PM: 6-choice menu (PM) 4:00 PM: Word Search: Kentucky Derby 6:30 PM: Kentucky Derby Watch Party (full TV broadcast 6-8 PM) | G5: 9:00 AM: Sunday Stretch + Walk 10:30 AM: Garden & Plants Trivia 12:00 PM: Sunday Comics Read-Aloud + Garden Word List 1:30 PM: Sunday Hymn Listening 2:00 PM: 6-choice menu (PM) 4:00 PM: Word Search: Garden Meditation 6:30 PM: Live Music Night
A6: 4 Star Wars Day - 'May the 4th Be With You' | B6: 5 Cinco de Mayo | C6: 6 National Nurses Day & National Beverage Day | D6: 7 National Roast Leg of Lamb Day | E6: 8 V-E Day (Victory in Europe, 1945) & No Socks Day | F6: 9 National Lost Sock Memorial Day & National Train Day | G6: 10 Mother's Day & National Shrimp Day
A7: 9:00 AM: Cardio Dance: Star Wars Theme 10:30 AM: Star Wars Trivia 12:00 PM: Front-Page News + Movie Trivia 1:30 PM: Genealogy / Memoir Hour 2:00 PM: 6-choice menu (PM) 4:00 PM: Word Search: Star Wars Day 6:30 PM: Cards & Cocktails | B7: 9:00 AM: Salsa Cardio Class 10:30 AM: Mexico & Cinco de Mayo Trivia 12:00 PM: Cinco de Mayo Word Search (Spanish-English) 1:30 PM: Crossword & Sudoku Cafe 2:00 PM: 6-choice menu (PM) 4:00 PM: Word Search: Cinco de Mayo 6:30 PM: Wine & Cheese Salon | C7: 9:00 AM: Strength + Stretch Combination 10:30 AM: Famous Nurses Trivia 12:00 PM: Newspaper + 'Things My Mom/Nurse Said' Reminiscence 1:30 PM: Bridge or Pinochle Lessons 2:00 PM: 6-choice menu (PM) 4:00 PM: Word Search: Nurses Day 6:30 PM: Movie Night with Discussion | D7: 9:00 AM: 3-Mile Walking Club 10:30 AM: Greek & Mediterranean Trivia 12:00 PM: Garden Section + Flower Crossword (Easy) 1:30 PM: Greek Mythology Story Hour 2:00 PM: 6-choice menu (PM) 4:00 PM: Word Search: Garden Crossword Words 6:30 PM: Movie Night: 'On Golden Pond' (1981) | E7: 9:00 AM: Big Band Cardio Dance 10:30 AM: WWII & V-E Day Trivia 12:00 PM: V-E Day History Read + 1940s Word Search 1:30 PM: V-E Day Memory Hour 2:00 PM: 6-choice menu (PM) 4:00 PM: Word Search: V-E Day 1945 6:30 PM: Cards & Cocktails | F7: 9:00 AM: Walking Club + Train-Themed Music 10:30 AM: Trains & Travel Trivia 12:00 PM: Travel Section + Train Trivia 1:30 PM: Independent Puzzle Time 2:00 PM: 6-choice menu (PM) 4:00 PM: Word Search: National Train Day 6:30 PM: Wine & Cheese Salon | G7: 9:00 AM: Sunday Calm Yoga 10:30 AM: Famous Mothers Trivia 12:00 PM: Sunday Paper + 'Mom's Wisdom' Word List 1:30 PM: Mother's Day Memory Hour 2:00 PM: 6-choice menu (PM) 4:00 PM: Word Search: Mother's Day 6:30 PM: Movie Night: 'Steel Magnolias' (1989)
A8: 11 National Eat What You Want Day | B8: 12 International Nurses Day & National Limerick Day | C8: 13 National Apple Pie Day & National Frog Jumping Day | D8: 14 National Buttermilk Biscuit Day | E8: 15 National Chocolate Chip Day | F8: 16 Armed Forces Day (3rd Saturday) & National BBQ Day | G8: 17 National Walnut Day
A9: 9:00 AM: Balance & Falls Prevention Class 10:30 AM: Food Favorites Trivia 12:00 PM: Food Section + 'Eat What You Want' Vote 1:30 PM: Crossword & Sudoku Cafe 2:00 PM: 6-choice menu (PM) 4:00 PM: Word Search: Eat What You Want 6:30 PM: Live Music Night | B9: 9:00 AM: Tai Chi Class 10:30 AM: Limericks & Wordplay Trivia 12:00 PM: Limerick Day Special 1:30 PM: Hand Massage + Soft Music 2:00 PM: 6-choice menu (PM) 4:00 PM: Limerick Composing Workshop 6:30 PM: Cards & Cocktails | C9: 9:00 AM: Apple Pie Energizer 10:30 AM: Apple Pie Trivia 12:00 PM: Food Section + Apple Pie Recipe Read-Aloud 1:30 PM: Book Club Quiet Reading 2:00 PM: 6-choice menu (PM) 4:00 PM: Word Search: Apple Pie & Frogs 6:30 PM: Wine & Cheese Salon | D9: 9:00 AM: Country Music Movement: 'Biscuit Stretch' 10:30 AM: Southern Cooking Trivia 12:00 PM: Food Section + Biscuit Recipe Reminiscence 1:30 PM: Newspaper & Discussion 2:00 PM: 6-choice menu (PM) 4:00 PM: Word Search: Buttermilk Biscuit 6:30 PM: Biscuit + Tea Wind-Down | E9: 9:00 AM: Yoga Flow Class 10:30 AM: Cookies & Sweets Trivia 12:00 PM: Newspaper + Chocolate Chip Cookie History 1:30 PM: Independent Puzzle Time 2:00 PM: 6-choice menu (PM) 4:00 PM: Word Search: Chocolate Chip 6:30 PM: Live Music Night | F9: 9:00 AM: Patriotic Walking Club 10:30 AM: Armed Forces Trivia 12:00 PM: Newspaper + Military Branches Word Match 1:30 PM: Veterans Photo Reminiscence 2:00 PM: 6-choice menu (PM) 4:00 PM: Word Search: Armed Forces Day 6:30 PM: Movie Night: 'The Best Years of Our Lives' (1946) Pt 1 | G9: 9:00 AM: Sunday Stretch or Hike 10:30 AM: Walnut & Trees Trivia 12:00 PM: Sunday Comics + Walnut Trivia 1:30 PM: Walnut Bread + Quiet Hour 2:00 PM: 6-choice menu (PM) 4:00 PM: Word Search: Walnut Day 6:30 PM: Wine & Cheese Salon
A10: 18 International Museum Day | B10: 19 National Devil's Food Cake Day | C10: 20 National Pick Strawberries Day | D10: 21 🇮🇹 TRAVEL DAY: Italy | E10: 22 National Maritime Day & National Vanilla Pudding Day | F10: 23 National Lucky Penny Day & World Turtle Day | G10: 24 National Scavenger Hunt Day
A11: 9:00 AM: Walking Tour: Local Art Walk 10:30 AM: Famous Museums Trivia 12:00 PM: Newspaper + Art Trivia 1:30 PM: Bridge or Pinochle Lessons 2:00 PM: 6-choice menu (PM) 4:00 PM: Word Search: Museum Day 6:30 PM: Movie Night with Discussion | B11: 9:00 AM: Resistance Band: Lower Body 10:30 AM: Cake & Chocolate Trivia 12:00 PM: Food Section + Devil's Food Cake History 1:30 PM: Book Club Quiet Reading 2:00 PM: 6-choice menu (PM) 4:00 PM: Word Search: Devil's Food Cake 6:30 PM: Live Music Night | C11: 9:00 AM: Strawberry Field Trip Walk 10:30 AM: Strawberry & Berry Trivia 12:00 PM: Newspaper + Strawberry Recipe Read 1:30 PM: Newspaper & Discussion 2:00 PM: 6-choice menu (PM) 4:00 PM: Word Search: Strawberry Picking 6:30 PM: Strawberry Sundae Wind-Down | D11: 9:00 AM: Italian Stretch & Opera 10:30 AM: ITALY TRAVEL DAY Trivia 12:00 PM: Headlines + Italian Travel Section 1:30 PM: 🇮🇹 Italian Music & Espresso 2:00 PM: 6-choice menu (PM) 4:00 PM: 🇮🇹 Italian Word Find 6:30 PM: 🇮🇹 Italian Cinema Night: 'Life Is Beautiful' (1997) | E11: 9:00 AM: Big Band + Maritime Cardio 10:30 AM: Maritime & Sailing Trivia 12:00 PM: Newspaper + Maritime Day Word Search 1:30 PM: Genealogy / Memoir Hour 2:00 PM: 6-choice menu (PM) 4:00 PM: Word Search: Maritime Day 6:30 PM: Movie Night with Discussion | F11: 9:00 AM: Walking Club + Penny Hunt 10:30 AM: Lucky Penny & Turtles Trivia 12:00 PM: Newspaper + Penny Trivia 1:30 PM: Crossword & Sudoku Cafe 2:00 PM: 6-choice menu (PM) 4:00 PM: Word Search: Lucky Penny / Turtle 6:30 PM: Live Music Night | G11: 9:00 AM: Sunday Walk or Stretch 10:30 AM: Scavenger & Discovery Trivia 12:00 PM: Sunday Paper + Scavenger Hunt Word List 1:30 PM: Sunday Reflection Hour 2:00 PM: 6-choice menu (PM) 4:00 PM: Word Search: Scavenger Hunt 6:30 PM: Cards & Cocktails
A12: 25 MEMORIAL DAY & National Wine Day | B12: 26 National Blueberry Cheesecake Day & National Paper Airplane Day | C12: 27 National Grape Popsicle Day & Sun Screen Day | D12: 28 National Hamburger Day & Senior Health & Fitness Day | E12: 29 JFK's Birthday & National Coq au Vin Day | F12: 30 National Mint Julep Day | G12: 31 National Macaroon Day
A13: 9:00 AM: Memorial Day Walking Ceremony 10:30 AM: Memorial Day Trivia 12:00 PM: Newspaper + Memorial Day Reading 1:30 PM: Veterans Reflection Hour 2:00 PM: 6-choice menu (PM) 4:00 PM: Memorial Day Word Find 6:30 PM: Movie Night: 'The Notebook' (2004) - Memorial Day | B13: 9:00 AM: Quick Full Body Class 10:30 AM: Blueberry & Paper Airplane Trivia 12:00 PM: Newspaper + Paper Airplane Folding 1:30 PM: Newspaper & Discussion 2:00 PM: 6-choice menu (PM) 4:00 PM: Word Search: Paper Airplane / Cake 6:30 PM: Movie Night with Discussion | C13: 9:00 AM: Yoga Sun Salutation Series 10:30 AM: Sun & Summer Trivia 12:00 PM: Newspaper + Sun & Skin Care Tips 1:30 PM: Independent Puzzle Time 2:00 PM: 6-choice menu (PM) 4:00 PM: Word Search: Sun & Sun Screen 6:30 PM: Live Music Night | D13: 9:00 AM: Senior Health & Fitness Day Workout 10:30 AM: Hamburger & Burger Trivia 12:00 PM: Newspaper + Health Tips Trivia 1:30 PM: Genealogy / Memoir Hour 2:00 PM: 6-choice menu (PM) 4:00 PM: Word Search: Hamburger Day 6:30 PM: Cards & Cocktails | E13: 9:00 AM: Camelot Era Dance Class 10:30 AM: 1960s & JFK Trivia 12:00 PM: Newspaper + JFK Reminiscence Word List 1:30 PM: Crossword & Sudoku Cafe 2:00 PM: 6-choice menu (PM) 4:00 PM: Word Search: 60s Decade 6:30 PM: Movie Night: 'Hidden Figures' (2016) | F13: 9:00 AM: Saturday Outdoor Walk 10:30 AM: Mint Julep & Drinks Trivia 12:00 PM: Newspaper + Mint Julep Recipe Read 1:30 PM: Bridge or Pinochle Lessons 2:00 PM: 6-choice menu (PM) 4:00 PM: Word Search: Mint Julep / Derby Closing 6:30 PM: Movie Night with Discussion | G13: 9:00 AM: Closing Day Choice Class 10:30 AM: May in Review Trivia 12:00 PM: Sunday Comics + 'Goodbye May' Word List 1:30 PM: May in Review Slideshow 2:00 PM: 6-choice menu (PM) 4:00 PM: Word Search: Macaroon & May Closing 6:30 PM: Movie Night: 'The Sound of Music' (1965)
A15: GOLD = Major Holiday | LIGHT GOLD = Bonus Event Day | ORANGE = TRAVEL DAY (May 21 - Italy) | LIGHT BLUE = Weekend | Times shown are defaults - can be adjusted.

Sheet Daily - MC
A1: Date | B1: Day | C1: Holiday/Theme | D1: Time | E1: Slot | F1: Activity Title | G1: Description / Notes
A2: May 1 | B2: Friday | C2: May Day & National Mother Goose Day | D2: 9:00 AM | E2: 🌊 Sunrise Stretch | F2: Sensory Spring Stretch | G2: Gentle 20-min seated stretch. Hand a fresh flower or sprig of mint to each resident to hold and smell during breathing. Soft floral music.
A3: May 1 | B3: Friday | C3: May Day & National Mother Goose Day | D3: 10:30 AM | E3: 🧠 Trivia Tides | F3: 'Welcome to May' Trivia | G3: 5 light questions to open the month. (1) What flower symbolizes May Day? (Lily of the valley) (2) What dance tradition uses ribbons around a tall pole? (Maypole) (3) Mother Goose Day is May 1 - name a Mother Goose rhyme. (Many: Hey Diddle Diddle, etc.) (4) What sport's biggest race is the first Saturday of May? (Horse racing - Derby) (5) What flower has the most variety in May? (Tulips, roses, irises - all valid). MC: ask one question at a time, give multiple-choice. AL/IL: open answer.
A4: May 1 | B4: Friday | C4: May Day & National Mother Goose Day | D4: 12:00 PM | E4: 📰 Headlines at the Helm | F4: 'Welcome to May' Word Search | G4: Read morning headlines aloud (weather, sports, light human-interest). Distribute the May Day word search (large print on Word Puzzle sheet #1). Words: MAYDAY, FLOWERS, SPRING, BASKET, RIBBON, MAYPOLE, BLOOM, BIRDS, GREEN, WARM. MC: do as a group on a whiteboard with leader pointing.
A5: May 1 | B5: Friday | C5: May Day & National Mother Goose Day | D5: 1:30 PM | E5: 🌿 Mellow Moorings | F5: Hand Massage with Lotion | G5: Aide-led hand massage with scented lotion. Soft music. 25 min. Calming and connecting.
A6: May 1 | B6: Friday | C6: May Day & National Mother Goose Day | D6: 2:00 PM | E6: ⚓ Anchor's Choice | F6: Anchor's Choice (6-choice menu) | G6: 🎲 Game: Picture Bingo - Simplified 4x4 Bingo with picture cards (animals, flowers). Aide assists with marker placement. Small treats as prizes. ☕ Social: Reminiscence Circle - Pass familiar objects (rolling pin, dial phone, bonnet) around the circle. Each resident holds and shares any memory it sparks. Coffee and cookies. 🎵 Music: Familiar Songs Sing-Along - Hymns and standards from the 30s-50s ('Amazing Grace,' 'You Are My Sunshine'). Lyrics on large-print sheets. Volunteer pianist if available. 🍰 Food: Cookie & Milk Social - Sugar cookies and warm milk. Simple, comforting. Sit-down with one staff per 4 residents. Conversation prompts about childhood treats. 🎨 Crafts: May Basket Decorating - Decorate paper cones. Fill with flowers and a candy. Hang on neighbors' doors. MC: pre-cut, resident adds final touches. 🌿 Outdoor: Patio Sitting & Birdwatching - Shaded patio. Bird feeders refilled. Soft music. Light snacks and lemonade. Walking residents can do a slow lap.
A7: May 1 | B7: Friday | C7: May Day & National Mother Goose Day | D7: 4:00 PM | E7: 🔤 Word Waves | F7: Word Search: May Day & Spring | G7: Today's themed word search (May Day & Spring). Large-print version distributed at every table. Words: MAYDAY, SPRING, FLOWERS, BASKET, RIBBON, BLOOM, BIRDS, GREEN. 25 min. AL/IL: independent. MC: leader does it on a whiteboard with the group, calls out and points.
A8: May 1 | B8: Friday | C8: May Day & National Mother Goose Day | D8: 6:30 PM | E8: 🌅 Sunset Social | F8: Lawrence Welk + Chamomile Tea | G8: Familiar musical TV show or DVD. Tea. Lights low but not off. 45 min.
A9: May 2 | B9: Saturday | C9: Kentucky Derby Day (1st Saturday) | D9: 9:00 AM | E9: 🌊 Sunrise Stretch | F9: Music & Movement: Marching Songs | G9: Seated march in place to 'Camptown Races,' 'Old Susanna.' Tap thighs to the beat. 15-20 min.
A10: May 2 | B10: Saturday | C10: Kentucky Derby Day (1st Saturday) | D10: 10:30 AM | E10: 🧠 Trivia Tides | F10: Kentucky Derby Trivia | G10: (1) What flower wraps the Derby winner? (Red roses) (2) How long is the Derby race? (1.25 miles) (3) Name a Triple Crown winner. (Secretariat, Affirmed, American Pharoah, Justify) (4) What state hosts the Derby? (Kentucky) (5) What's the official Derby drink? (Mint julep). MC: focus on visuals - show pictures of horses, hats, roses.
A11: May 2 | B11: Saturday | C11: Kentucky Derby Day (1st Saturday) | D11: 12:00 PM | E11: 📰 Headlines at the Helm | F11: Sports Headlines + Famous Horses Trivia | G11: Read the day's sports section, especially Derby coverage. Trivia card: name three Triple Crown winners (Secretariat 1973, Affirmed 1978, American Pharoah 2015, Justify 2018). Group word scramble: HORSESHOE, JOCKEY, DERBY, ROSES, BLANKET.
A12: May 2 | B12: Saturday | C12: Kentucky Derby Day (1st Saturday) | D12: 1:30 PM | E12: 🌿 Mellow Moorings | F12: Derby Day Reading | G12: Magazines and books about horses, the Derby, Kentucky. Comfort chairs. Mint lemonade. 30 min.
... A218: May 31 | B218: Sunday | C218: National Macaroon Day | D218: 6:30 PM | E218: 🌅 Sunset Social | F218: May Closing Music Hour | G218: Photo slideshow + music from the month. Tea. 45 min.

Sheet Daily - AL
A1: Date | B1: Day | C1: Holiday/Theme | D1: Time | E1: Slot | F1: Activity Title | G1: Description / Notes
A2: May 1 | B2: Friday | C2: May Day & National Mother Goose Day | D2: 9:00 AM | E2: 🌊 Sunrise Stretch | F2: Chair Yoga: Spring Awakening | G2: Gentle 25-min seated yoga sequence with a flower-and-garden visualization. Focus on shoulder rolls, neck stretches, hip openers. Bring a fresh flower for each resident to hold during closing breath. AL: standing balance pose option. MC: leader demonstrates each move slowly, repeats cues. SN: passive range-of-motion assistance for those who need it.
A3: May 1 | B3: Friday | C3: May Day & National Mother Goose Day | D3: 10:30 AM | E3: 🧠 Trivia Tides | F3: 'Welcome to May' Trivia | G3: 5 light questions to open the month. (1) What flower symbolizes May Day? (Lily of the valley) (2) What dance tradition uses ribbons around a tall pole? (Maypole) (3) Mother Goose Day is May 1 - name a Mother Goose rhyme. (Many: Hey Diddle Diddle, etc.) (4) What sport's biggest race is the first Saturday of May? (Horse racing - Derby) (5) What flower has the most variety in May? (Tulips, roses, irises - all valid). MC: ask one question at a time, give multiple-choice. AL/IL: open answer.
A4: May 1 | B4: Friday | C4: May Day & National Mother Goose Day | D4: 12:00 PM | E4: 📰 Headlines at the Helm | F4: 'Welcome to May' Word Search | G4: Read morning headlines aloud (weather, sports, light human-interest). Distribute the May Day word search (large print on Word Puzzle sheet #1). Words: MAYDAY, FLOWERS, SPRING, BASKET, RIBBON, MAYPOLE, BLOOM, BIRDS, GREEN, WARM. MC: do as a group on a whiteboard with leader pointing.
A5: May 1 | B5: Friday | C5: May Day & National Mother Goose Day | D5: 1:30 PM | E5: 🌿 Mellow Moorings | F5: Quiet Reading Hour | G5: Newspapers, magazines, large-print books. Coffee available. Soft background music. 30 min.
A6: May 1 | B6: Friday | C6: May Day & National Mother Goose Day | D6: 2:00 PM | E6: ⚓ Anchor's Choice | F6: Anchor's Choice (6-choice menu) | G6: 🎲 Game: Bingo - Standard 30-min Bingo. Large-print cards. Caller speaks loudly and clearly. Prizes: small toiletries, costume jewelry, candy. ☕ Social: Coffee & Conversation Hour - Pot of coffee, tea, cookies. Open-table format. Activity director suggests a conversation topic. 🎵 Music: Decade Sing-Along - Lyric sheets to favorites from the 50s-70s. Volunteer pianist or recorded music. 60 min. 🍰 Food: Themed Snack Bar - Build-your-own snack bar (sundae, trail mix, crackers + cheese). Light refreshment hour. 🎨 Crafts: May Basket Decorating - Decorate paper cones. Fill with flowers and a candy. Hang on neighbors' doors. AL: full participation. 🌿 Outdoor: Garden Stroll & Bench Time - Outdoor walking club through the gardens. Stop at benches. Identify flowers along the way.
A7: May 1 | B7: Friday | C7: May Day & National Mother Goose Day | D7: 4:00 PM | E7: 🔤 Word Waves | F7: Word Search: May Day & Spring | G7: Today's themed word search (May Day & Spring). Large-print version distributed at every table. Words: MAYDAY, SPRING, FLOWERS, BASKET, RIBBON, BLOOM, BIRDS, GREEN. 25 min. AL/IL: independent. MC: leader does it on a whiteboard with the group, calls out and points.
A8: May 1 | B8: Friday | C8: May Day & National Mother Goose Day | D8: 6:30 PM | E8: 🌅 Sunset Social | F8: 'Driving Miss Daisy' (1989) - Wind Down | G8: Soft popcorn, lemonade, lights dim. Optional. Quieter alternative in side lounge: cards, soft music.
A9: May 2 | B9: Saturday | C9: Kentucky Derby Day (1st Saturday) | D9: 9:00 AM | E9: 🌊 Sunrise Stretch | F9: Derby Day Warm-Up | G9: Themed energizer: 'horses at the gate' marching in place 1 min, 'reaching for the roses' overhead reach x10, 'galloping arms' alternating reach x20, ankle circles, seated kicks. End with 'Photo finish!' freeze pose. Play 'Camptown Races' as background. ~25 min.
A10: May 2 | B10: Saturday | C10: Kentucky Derby Day (1st Saturday) | D10: 10:30 AM | E10: 🧠 Trivia Tides | F10: Kentucky Derby Trivia | G10: (1) What flower wraps the Derby winner? (Red roses) (2) How long is the Derby race? (1.25 miles) (3) Name a Triple Crown winner. (Secretariat, Affirmed, American Pharoah, Justify) (4) What state hosts the Derby? (Kentucky) (5) What's the official Derby drink? (Mint julep). MC: focus on visuals - show pictures of horses, hats, roses.
A11: May 2 | B11: Saturday | C11: Kentucky Derby Day (1st Saturday) | D11: 12:00 PM | E11: 📰 Headlines at the Helm | F11: Sports Headlines + Famous Horses Trivia | G11: Read the day's sports section, especially Derby coverage. Trivia card: name three Triple Crown winners (Secretariat 1973, Affirmed 1978, American Pharoah 2015, Justify 2018). Group word scramble: HORSESHOE, JOCKEY, DERBY, ROSES, BLANKET.
A12: May 2 | B12: Saturday | C12: Kentucky Derby Day (1st Saturday) | D12: 1:30 PM | E12: 🌿 Mellow Moorings | F12: Derby Day Reading | G12: Magazines and books about horses, the Derby, Kentucky. Comfort chairs. Mint lemonade. 30 min.
... A218: May 31 | B218: Sunday | C218: National Macaroon Day | D218: 6:30 PM | E218: 🌅 Sunset Social | F218: Sing-Along Hour | G218: Volunteer pianist or recorded music. Lyric sheets. Mix of decades. 60 min.

Sheet Daily - IL
A1: Date | B1: Day | C1: Holiday/Theme | D1: Time | E1: Slot | F1: Activity Title | G1: Description / Notes
A2: May 1 | B2: Friday | C2: May Day & National Mother Goose Day | D2: 9:00 AM | E2: 🌊 Sunrise Stretch | F2: Walking Club + Yoga (Choice) | G2: 30-min walking club outside or 30-min standing yoga (instructor-led). Resident picks. Springtime kick-off.
A3: May 1 | B3: Friday | C3: May Day & National Mother Goose Day | D3: 10:30 AM | E3: 🧠 Trivia Tides | F3: 'Welcome to May' Trivia | G3: 5 light questions to open the month. (1) What flower symbolizes May Day? (Lily of the valley) (2) What dance tradition uses ribbons around a tall pole? (Maypole) (3) Mother Goose Day is May 1 - name a Mother Goose rhyme. (Many: Hey Diddle Diddle, etc.) (4) What sport's biggest race is the first Saturday of May? (Horse racing - Derby) (5) What flower has the most variety in May? (Tulips, roses, irises - all valid). MC: ask one question at a time, give multiple-choice. AL/IL: open answer.
A4: May 1 | B4: Friday | C4: May Day & National Mother Goose Day | D4: 12:00 PM | E4: 📰 Headlines at the Helm | F4: 'Welcome to May' Word Search | G4: Read morning headlines aloud (weather, sports, light human-interest). Distribute the May Day word search (large print on Word Puzzle sheet #1). Words: MAYDAY, FLOWERS, SPRING, BASKET, RIBBON, MAYPOLE, BLOOM, BIRDS, GREEN, WARM. MC: do as a group on a whiteboard with leader pointing.
A5: May 1 | B5: Friday | C5: May Day & National Mother Goose Day | D5: 1:30 PM | E5: 🌿 Mellow Moorings | F5: Book Club Quiet Reading | G5: Members read this month's book selection. Coffee. Discussion saved for later in the week. 45 min.
A6: May 1 | B6: Friday | C6: May Day & National Mother Goose Day | D6: 2:00 PM | E6: ⚓ Anchor's Choice | F6: Anchor's Choice (6-choice menu) | G6: 🎲 Game: Card Tournament - Skip-Bo, Bridge, Hand-and-Foot, Pinochle - whatever the community plays. Multiple tables. Track winners on a leaderboard. ☕ Social: Current Events Discussion - Activity director brings 3-5 articles from the morning paper. Group discusses. Coffee and tea. 60 min. 🎵 Music: Music Trivia Hour - Name That Tune format with 5-second clips spanning 6 decades. Team scoring. Friendly competition. 🍰 Food: Cooking Demo + Tasting - Activity director or kitchen demos a recipe. Residents help when possible. Tastings provided. 🎨 Crafts: May Basket Decorating - Decorate paper cones. Fill with flowers and a candy. Hang on neighbors' doors. IL: design from scratch with paper, ribbon, and live flowers. 🌿 Outdoor: Garden Club Workday - Light gardening - watering, deadheading, planting seedlings. Sunscreen and hats provided.
A7: May 1 | B7: Friday | C7: May Day & National Mother Goose Day | D7: 4:00 PM | E7: 🔤 Word Waves | F7: Word Search: May Day & Spring | G7: Today's themed word search (May Day & Spring). Large-print version distributed at every table. Words: MAYDAY, SPRING, FLOWERS, BASKET, RIBBON, BLOOM, BIRDS, GREEN. 25 min. AL/IL: independent. MC: leader does it on a whiteboard with the group, calls out and points.
A8: May 1 | B8: Friday | C8: May Day & National Mother Goose Day | D8: 6:30 PM | E8: 🌅 Sunset Social | F8: Movie Night: 'Driving Miss Daisy' (1989) | G8: Full feature film. Popcorn, snacks, mocktails. Optional discussion after.
A9: May 2 | B9: Saturday | C9: Kentucky Derby Day (1st Saturday) | D9: 9:00 AM | E9: 🌊 Sunrise Stretch | F9: Resistance Band Strength Class | G9: Full body 30-min strength class with bands. Standing or seated. Trainer or volunteer leads.
A10: May 2 | B10: Saturday | C10: Kentucky Derby Day (1st Saturday) | D10: 10:30 AM | E10: 🧠 Trivia Tides | F10: Kentucky Derby Trivia | G10: (1) What flower wraps the Derby winner? (Red roses) (2) How long is the Derby race? (1.25 miles) (3) Name a Triple Crown winner. (Secretariat, Affirmed, American Pharoah, Justify) (4) What state hosts the Derby? (Kentucky) (5) What's the official Derby drink? (Mint julep). MC: focus on visuals - show pictures of horses, hats, roses.
A11: May 2 | B11: Saturday | C11: Kentucky Derby Day (1st Saturday) | D11: 12:00 PM | E11: 📰 Headlines at the Helm | F11: Sports Headlines + Famous Horses Trivia | G11: Read the day's sports section, especially Derby coverage. Trivia card: name three Triple Crown winners (Secretariat 1973, Affirmed 1978, American Pharoah 2015, Justify 2018). Group word scramble: HORSESHOE, JOCKEY, DERBY, ROSES, BLANKET.
A12: May 2 | B12: Saturday | C12: Kentucky Derby Day (1st Saturday) | D12: 1:30 PM | E12: 🌿 Mellow Moorings | F12: Derby Day Reading | G12: Magazines and books about horses, the Derby, Kentucky. Comfort chairs. Mint lemonade. 30 min.
... A218: May 31 | B218: Sunday | C218: National Macaroon Day | D218: 6:30 PM | E218: 🌅 Sunset Social | F218: Movie Night: 'The Sound of Music' (1965) | G218: Full feature film. Popcorn, snacks, mocktails. Optional discussion after.

Sheet Bonus Events
A1: May 2026 - BONUS MONTHLY EVENTS
A3: Date | B3: Event | C3: Description | D3: Supplies Needed | E3: Lead Staff
A4: May 2 | B4: Kentucky Derby Watch Party | C4: Gather residents in the activity room with a TV tuned to NBC's Derby coverage (post time around 6:45 PM ET). Set up a 'Run for the Roses' theme: red rose centerpieces, paper fancy hats for residents to decorate, mock $1 betting slips (use poker chips, no real wagering), mint juleps (mocktail or alcoholic per facility policy), and a pre-race trivia game about famous Triple Crown winners. Print a list of the entered horses so residents can pick a favorite. MC adaptation: pre-decorated hats; play 'My Old Kentucky Home' on a loop. | D4: TV, paper hats, ribbons/feathers/glue, red roses, mint mocktails, play money, race-day printable
A5: May 5 | B5: Cinco de Mayo Fiesta | C5: Mid-afternoon fiesta with mariachi music playlist, paper flag banners, guacamole-and-chip station (or tortilla pinwheels for soft diets), non-alcoholic agua fresca, and a piñata-style 'tap with a paddle' alternative where residents take turns tapping a hanging crepe-paper container that breaks open easily. Mexican loteria can be played as a Bingo variant - we have a printable card on the Word Game tab. | D5: Mariachi music, decorations, snacks, loteria cards, soft piñata
A6: May 8 | B6: Mother's Day Tea (Pre-celebration) | C6: High tea event timed before Mother's Day so visiting families can attend. Set tables with linen, china teacups, finger sandwiches (cucumber, egg salad), scones with jam, lemon bars. Live or recorded harp / piano music. Honor every female resident as a 'mother figure' regardless of biological motherhood. Hand out fresh flower corsages or boutonnieres. Have a memory book at each table where families and residents can record favorite memories of their own mothers. | D6: Tea service, finger foods, flowers, memory books/pens, soft music
A7: May 16 | B7: Armed Forces Day Honor Ceremony | C7: 30-minute ceremony in the dining room recognizing veteran residents and staff. Display branch flags (Army, Navy, Air Force, Marines, Coast Guard, Space Force). Each veteran resident receives a hand-signed thank-you card prepared by local schoolchildren or staff in advance. Play patriotic music (anthems of each branch). Invite a local color guard or scout troop if available. Serve red, white, and blue cupcakes. Photograph each veteran for the family bulletin board. | D7: Flags, thank-you cards, patriotic playlist, cupcakes, camera
A8: May 25 | B8: Memorial Day Cookout & Remembrance | C8: All-facility outdoor (weather permitting) or activity-room cookout. Hot dogs, hamburgers, potato salad, watermelon, lemonade, and ice cream. Live music if budget allows - otherwise a curated patriotic + 1950s-60s playlist. Brief moment of silence at noon (national tradition). Display photos of veteran residents in uniform. Outdoor games: horseshoes (lightweight rubber), corn-hole, lawn bowling. MC/SN: shaded patio seating, pinwheels and flags to hold, music focus. | D8: Cookout food, beverages, decorations, lawn games, sound system
A9: May 28 | B9: Senior Health & Fitness Fair | C9: Half-day mini-fair with stations residents rotate through: (1) Blood pressure check by nursing staff, (2) Hand-grip strength assessment, (3) Hydration education + flavored water tasting, (4) Brain-game station with crosswords and Sudoku, (5) Chair-yoga demo. Hand out 'Health Champion' ribbons to all participants. | D9: BP cuff, grip dynamometer, water/fruit, puzzles, ribbons

Sheet Holidays
A1: May 2026 HOLIDAYS & FUN DAYS
A3: Date | B3: Day | C3: Holiday / Theme
A4: May 1 | B4: Friday | C4: May Day & National Mother Goose Day
A5: May 2 | B5: Saturday | C5: Kentucky Derby Day (1st Saturday)
A6: May 3 | B6: Sunday | C6: National Garden Meditation Day
A7: May 4 | B7: Monday | C7: Star Wars Day - 'May the 4th Be With You'
A8: May 5 | B8: Tuesday | C8: Cinco de Mayo
A9: May 6 | B9: Wednesday | C9: National Nurses Day & National Beverage Day
A10: May 7 | B10: Thursday | C10: National Roast Leg of Lamb Day
A11: May 8 | B11: Friday | C11: V-E Day (Victory in Europe, 1945) & No Socks Day
A12: May 9 | B12: Saturday | C12: National Lost Sock Memorial Day & National Train Day
A13: May 10 | B13: Sunday | C13: Mother's Day & National Shrimp Day
A14: May 11 | B14: Monday | C14: National Eat What You Want Day
... A34: May 31 | B34: Sunday | C34: National Macaroon Day

Sheet Roster
A1: RESIDENT ROSTER
A2: Replace placeholder names with your residents. Tag each with MC / AL / IL. Names auto-flow into the Charting tabs.
A4: # | B4: Resident Name | C4: Care Level (MC/AL/IL) | D4: Notes
A5: 1 | B5: Resident 1 | C5: AL
A6: 2 | B6: Resident 2 | C6: AL
A7: 3 | B7: Resident 3 | C7: AL
A8: 4 | B8: Resident 4 | C8: AL
A9: 5 | B9: Resident 5 | C9: AL
A10: 6 | B10: Resident 6 | C10: AL
A11: 7 | B11: Resident 7 | C11: AL
A12: 8 | B12: Resident 8 | C12: AL
A13: 9 | B13: Resident 9 | C13: AL
A14: 10 | B14: Resident 10 | C14: AL
A15: 11 | B15: Resident 11 | C15: AL
A16: 12 | B16: Resident 12 | C16: AL
... A19: 15 | B19: Resident 15 | C19: AL
A20: 16
A21: 17
A22: 18
A23: 19
A24: 20
A25: 21
A26: 22
A27: 23
A28: 24
A29: 25
A30: 26
A31: 27
... A34: 30

Sheet Charting - MC
A1: PARTICIPATION CHARTING - MEMORY CARE - May 2026
A2: Codes: A = Active | O = Observed | D = Declined | N/A = Not Available | Blank = no record
A3: RESIDENT | B3: 1 Fri | I3: 2 Sat | P3: 3 Sun | W3: 4 Mon | AD3: 5 Tue | AK3: 6 Wed | AR3: 7 Thu | AY3: 8 Fri | BF3: 9 Sat | BM3: 10 Sun | BT3: 11 Mon | CA3: 12 Tue | CH3: 13 Wed | CO3: 14 Thu | CV3: 15 Fri | DC3: 16 Sat | DJ3: 17 Sun | DQ3: 18 Mon | DX3: 19 Tue | EE3: 20 Wed | EL3: 21 Thu | ES3: 22 Fri | EZ3: 23 Sat | FG3: 24 Sun | FN3: 25 Mon | FU3: 26 Tue | GB3: 27 Wed | GI3: 28 Thu | GP3: 29 Fri | GW3: 30 Sat | HD3: 31 Sun | HK3: Active | HL3: Observed | HM3: Declined | HN3: N/A | HO3: Engage %
B4: AM | C4: Triv | D4: News | E4: Mlw | F4: PM | G4: Word | H4: Eve | I4: AM | J4: Triv | K4: News | L4: Mlw | M4: PM | N4: Word | O4: Eve | P4: AM | Q4: Triv | R4: News | S4: Mlw | T4: PM | U4: Word | V4: Eve | W4: AM | X4: Triv | Y4: News | Z4: Mlw | AA4: PM | AB4: Word | AC4: Eve | AD4: AM | AE4: Triv | AF4: News | AG4: Mlw | AH4: PM | AI4: Word | AJ4: Eve | AK4: AM | AL4: Triv | AM4: News | AN4: Mlw | AO4: PM | AP4: Word | AQ4: Eve | AR4: AM | AS4: Triv | AT4: News | AU4: Mlw | AV4: PM | AW4: Word | AX4: Eve | AY4: AM | AZ4: Triv | BA4: News | BB4: Mlw | BC4: PM | BD4: Word | BE4: Eve | BF4: AM | BG4: Triv | BH4: News | BI4: Mlw | BJ4: PM | BK4: Word | BL4: Eve | BM4: AM | BN4: Triv | BO4: News | BP4: Mlw | BQ4: PM | BR4: Word | BS4: Eve | BT4: AM | BU4: Triv | BV4: News | BW4: Mlw | BX4: PM | BY4: Word | BZ4: Eve | CA4: AM | CB4: Triv | CC4: News | CD4: Mlw | CE4: PM | CF4: Word | CG4: Eve | CH4: AM | CI4: Triv | CJ4: News | CK4: Mlw | CL4: PM | CM4: Word | CN4: Eve | CO4: AM | CP4: Triv | CQ4: News | CR4: Mlw | CS4: PM | CT4: Word | CU4: Eve | CV4: AM | CW4: Triv | CX4: News | CY4: Mlw | CZ4: PM | DA4: Word | DB4: Eve | DC4: AM | DD4: Triv | DE4: News | DF4: Mlw | DG4: PM | DH4: Word | DI4: Eve | DJ4: AM | DK4: Triv | DL4: News | DM4: Mlw | DN4: PM | DO4: Word | DP4: Eve | DQ4: AM | DR4: Triv | DS4: News | DT4: Mlw | DU4: PM | DV4: Word | DW4: Eve | DX4: AM | DY4: Triv | DZ4: News | EA4: Mlw | EB4: PM | EC4: Word | ED4: Eve | EE4: AM | EF4: Triv | EG4: News | EH4: Mlw | EI4: PM | EJ4: Word | EK4: Eve | EL4: AM | EM4: Triv | EN4: News | EO4: Mlw | EP4: PM | EQ4: Word | ER4: Eve | ES4: AM | ET4: Triv | EU4: News | EV4: Mlw | EW4: PM | EX4: Word | EY4: Eve | EZ4: AM | FA4: Triv | FB4: News | FC4: Mlw | FD4: PM | FE4: Word | FF4: Eve | FG4: AM | FH4: Triv | FI4: News | FJ4: Mlw | FK4: PM | FL4: Word | FM4: Eve | FN4: AM | FO4: Triv | FP4: News | FQ4: Mlw | FR4: PM | FS4: Word | FT4: Eve | FU4: AM | FV4: Triv | FW4: News | FX4: Mlw | FY4: PM | FZ4: Word | GA4: Eve | GB4: AM | GC4: Triv | GD4: News | GE4: Mlw | GF4: PM | GG4: Word | GH4: Eve | GI4: AM | GJ4: Triv | GK4: News | GL4: Mlw | GM4: PM | GN4: Word | GO4: Eve | GP4: AM | GQ4: Triv | GR4: News | GS4: Mlw | GT4: PM | GU4: Word | GV4: Eve | GW4: AM | GX4: Triv | GY4: News | GZ4: Mlw | HA4: PM | HB4: Word | HC4: Eve | HD4: AM | HE4: Triv | HF4: News | HG4: Mlw | HH4: PM | HI4: Word | HJ4: Eve
A5: =Roster!B5 -> Resident 1 | HK5: =COUNTIF(B5:HJ5,"A") -> 0 | HL5: =COUNTIF(B5:HJ5,"O") -> 0 | HM5: =COUNTIF(B5:HJ5,"D") -> 0 | HN5: =COUNTIF(B5:HJ5,"N/A") -> 0 | HO5: =IFERROR((HK5+HL5)/(HK5+HL5+HM5),0) -> 0
A6: =Roster!B6 -> Resident 2 | HK6: =COUNTIF(B6:HJ6,"A") -> 0 | HL6: =COUNTIF(B6:HJ6,"O") -> 0 | HM6: =COUNTIF(B6:HJ6,"D") -> 0 | HN6: =COUNTIF(B6:HJ6,"N/A") -> 0 | HO6: =IFERROR((HK6+HL6)/(HK6+HL6+HM6),0) -> 0
A7: =Roster!B7 -> Resident 3 | HK7: =COUNTIF(B7:HJ7,"A") -> 0 | HL7: =COUNTIF(B7:HJ7,"O") -> 0 | HM7: =COUNTIF(B7:HJ7,"D") -> 0 | HN7: =COUNTIF(B7:HJ7,"N/A") -> 0 | HO7: =IFERROR((HK7+HL7)/(HK7+HL7+HM7),0) -> 0
A8: =Roster!B8 -> Resident 4 | HK8: =COUNTIF(B8:HJ8,"A") -> 0 | HL8: =COUNTIF(B8:HJ8,"O") -> 0 | HM8: =COUNTIF(B8:HJ8,"D") -> 0 | HN8: =COUNTIF(B8:HJ8,"N/A") -> 0 | HO8: =IFERROR((HK8+HL8)/(HK8+HL8+HM8),0) -> 0
A9: =Roster!B9 -> Resident 5 | HK9: =COUNTIF(B9:HJ9,"A") -> 0 | HL9: =COUNTIF(B9:HJ9,"O") -> 0 | HM9: =COUNTIF(B9:HJ9,"D") -> 0 | HN9: =COUNTIF(B9:HJ9,"N/A") -> 0 | HO9: =IFERROR((HK9+HL9)/(HK9+HL9+HM9),0) -> 0
A10: =Roster!B10 -> Resident 6 | HK10: =COUNTIF(B10:HJ10,"A") -> 0 | HL10: =COUNTIF(B10:HJ10,"O") -> 0 | HM10: =COUNTIF(B10:HJ10,"D") -> 0 | HN10: =COUNTIF(B10:HJ10,"N/A") -> 0 | HO10: =IFERROR((HK10+HL10)/(HK10+HL10+HM10),0) -> 0
A11: =Roster!B11 -> Resident 7 | HK11: =COUNTIF(B11:HJ11,"A") -> 0 | HL11: =COUNTIF(B11:HJ11,"O") -> 0 | HM11: =COUNTIF(B11:HJ11,"D") -> 0 | HN11: =COUNTIF(B11:HJ11,"N/A") -> 0 | HO11: =IFERROR((HK11+HL11)/(HK11+HL11+HM11),0) -> 0
A12: =Roster!B12 -> Resident 8 | HK12: =COUNTIF(B12:HJ12,"A") -> 0 | HL12: =COUNTIF(B12:HJ12,"O") -> 0 | HM12: =COUNTIF(B12:HJ12,"D") -> 0 | HN12: =COUNTIF(B12:HJ12,"N/A") -> 0 | HO12: =IFERROR((HK12+HL12)/(HK12+HL12+HM12),0) -> 0
A13: =Roster!B13 -> Resident 9 | HK13: =COUNTIF(B13:HJ13,"A") -> 0 | HL13: =COUNTIF(B13:HJ13,"O") -> 0 | HM13: =COUNTIF(B13:HJ13,"D") -> 0 | HN13: =COUNTIF(B13:HJ13,"N/A") -> 0 | HO13: =IFERROR((HK13+HL13)/(HK13+HL13+HM13),0) -> 0
A14: =Roster!B14 -> Resident 10 | HK14: =COUNTIF(B14:HJ14,"A") -> 0 | HL14: =COUNTIF(B14:HJ14,"O") -> 0 | HM14: =COUNTIF(B14:HJ14,"D") -> 0 | HN14: =COUNTIF(B14:HJ14,"N/A") -> 0 | HO14: =IFERROR((HK14+HL14)/(HK14+HL14+HM14),0) -> 0
A15: =Roster!B15 -> Resident 11 | HK15: =COUNTIF(B15:HJ15,"A") -> 0 | HL15: =COUNTIF(B15:HJ15,"O") -> 0 | HM15: =COUNTIF(B15:HJ15,"D") -> 0 | HN15: =COUNTIF(B15:HJ15,"N/A") -> 0 | HO15: =IFERROR((HK15+HL15)/(HK15+HL15+HM15),0) -> 0
A16: =Roster!B16 -> Resident 12 | HK16: =COUNTIF(B16:HJ16,"A") -> 0 | HL16: =COUNTIF(B16:HJ16,"O") -> 0 | HM16: =COUNTIF(B16:HJ16,"D") -> 0 | HN16: =COUNTIF(B16:HJ16,"N/A") -> 0 | HO16: =IFERROR((HK16+HL16)/(HK16+HL16+HM16),0) -> 0
... A34: =Roster!B34 -> 0 | HK34: =COUNTIF(B34:HJ34,"A") -> 0 | HL34: =COUNTIF(B34:HJ34,"O") -> 0 | HM34: =COUNTIF(B34:HJ34,"D") -> 0 | HN34: =COUNTIF(B34:HJ34,"N/A") -> 0 | HO34: =IFERROR((HK34+HL34)/(HK34+HL34+HM34),0) -> 0

Sheet Charting - AL
A1: PARTICIPATION CHARTING - ASSISTED LIVING - May 2026
A2: Codes: A = Active | O = Observed | D = Declined | N/A = Not Available | Blank = no record
A3: RESIDENT | B3: 1 Fri | I3: 2 Sat | P3: 3 Sun | W3: 4 Mon | AD3: 5 Tue | AK3: 6 Wed | AR3: 7 Thu | AY3: 8 Fri | BF3: 9 Sat | BM3: 10 Sun | BT3: 11 Mon | CA3: 12 Tue | CH3: 13 Wed | CO3: 14 Thu | CV3: 15 Fri | DC3: 16 Sat | DJ3: 17 Sun | DQ3: 18 Mon | DX3: 19 Tue | EE3: 20 Wed | EL3: 21 Thu | ES3: 22 Fri | EZ3: 23 Sat | FG3: 24 Sun | FN3: 25 Mon | FU3: 26 Tue | GB3: 27 Wed | GI3: 28 Thu | GP3: 29 Fri | GW3: 30 Sat | HD3: 31 Sun | HK3: Active | HL3: Observed | HM3: Declined | HN3: N/A | HO3: Engage %
